[2025-04-11 23:45:01,340] ERROR log_exception() L875  Exception on /contato [POST] - call_trace=/Users/josepatricio/Desktop/MVP PUC/Checkin_eVTOL/checkin/lib/python3.12/site-packages/flask/app.py L875 
Traceback (most recent call last):
  File "/Users/josepatricio/Desktop/MVP PUC/Checkin_eVTOL/checkin/lib/python3.12/site-packages/sqlalchemy/engine/base.py", line 1964, in _exec_single_context
    self.dialect.do_execute(
  File "/Users/josepatricio/Desktop/MVP PUC/Checkin_eVTOL/checkin/lib/python3.12/site-packages/sqlalchemy/engine/default.py", line 945, in do_execute
    cursor.execute(statement, parameters)
sqlite3.OperationalError: database is locked

The above exception was the direct cause of the following exception:

Traceback (most recent call last):
  File "/Users/josepatricio/Desktop/MVP PUC/Checkin_eVTOL/checkin/lib/python3.12/site-packages/flask/app.py", line 1511, in wsgi_app
    response = self.full_dispatch_request()
               ^^^^^^^^^^^^^^^^^^^^^^^^^^^^
  File "/Users/josepatricio/Desktop/MVP PUC/Checkin_eVTOL/checkin/lib/python3.12/site-packages/flask/app.py", line 919, in full_dispatch_request
    rv = self.handle_user_exception(e)
         ^^^^^^^^^^^^^^^^^^^^^^^^^^^^^
  File "/Users/josepatricio/Desktop/MVP PUC/Checkin_eVTOL/checkin/lib/python3.12/site-packages/flask_cors/extension.py", line 176, in wrapped_function
    return cors_after_request(app.make_response(f(*args, **kwargs)))
                                                ^^^^^^^^^^^^^^^^^^
  File "/Users/josepatricio/Desktop/MVP PUC/Checkin_eVTOL/checkin/lib/python3.12/site-packages/flask/app.py", line 917, in full_dispatch_request
    rv = self.dispatch_request()
         ^^^^^^^^^^^^^^^^^^^^^^^
  File "/Users/josepatricio/Desktop/MVP PUC/Checkin_eVTOL/checkin/lib/python3.12/site-packages/flask/app.py", line 902, in dispatch_request
    return self.ensure_sync(self.view_functions[rule.endpoint])(**view_args)  # type: ignore[no-any-return]
           ^^^^^^^^^^^^^^^^^^^^^^^^^^^^^^^^^^^^^^^^^^^^^^^^^^^^^^^^^^^^^^^^^
  File "/Users/josepatricio/Desktop/MVP PUC/Checkin_eVTOL/checkin/lib/python3.12/site-packages/flask_openapi3/scaffold.py", line 117, in view_func
    response = func(**func_kwargs)
               ^^^^^^^^^^^^^^^^^^^
  File "/Users/josepatricio/Desktop/MVP PUC/Checkin_eVTOL/Checkin_back/app.py", line 205, in add_contato
    session.commit()
  File "/Users/josepatricio/Desktop/MVP PUC/Checkin_eVTOL/checkin/lib/python3.12/site-packages/sqlalchemy/orm/session.py", line 2032, in commit
    trans.commit(_to_root=True)
  File "<string>", line 2, in commit
  File "/Users/josepatricio/Desktop/MVP PUC/Checkin_eVTOL/checkin/lib/python3.12/site-packages/sqlalchemy/orm/state_changes.py", line 139, in _go
    ret_value = fn(self, *arg, **kw)
                ^^^^^^^^^^^^^^^^^^^^
  File "/Users/josepatricio/Desktop/MVP PUC/Checkin_eVTOL/checkin/lib/python3.12/site-packages/sqlalchemy/orm/session.py", line 1313, in commit
    self._prepare_impl()
  File "<string>", line 2, in _prepare_impl
  File "/Users/josepatricio/Desktop/MVP PUC/Checkin_eVTOL/checkin/lib/python3.12/site-packages/sqlalchemy/orm/state_changes.py", line 139, in _go
    ret_value = fn(self, *arg, **kw)
                ^^^^^^^^^^^^^^^^^^^^
  File "/Users/josepatricio/Desktop/MVP PUC/Checkin_eVTOL/checkin/lib/python3.12/site-packages/sqlalchemy/orm/session.py", line 1288, in _prepare_impl
    self.session.flush()
  File "/Users/josepatricio/Desktop/MVP PUC/Checkin_eVTOL/checkin/lib/python3.12/site-packages/sqlalchemy/orm/session.py", line 4353, in flush
    self._flush(objects)
  File "/Users/josepatricio/Desktop/MVP PUC/Checkin_eVTOL/checkin/lib/python3.12/site-packages/sqlalchemy/orm/session.py", line 4488, in _flush
    with util.safe_reraise():
  File "/Users/josepatricio/Desktop/MVP PUC/Checkin_eVTOL/checkin/lib/python3.12/site-packages/sqlalchemy/util/langhelpers.py", line 146, in __exit__
    raise exc_value.with_traceback(exc_tb)
  File "/Users/josepatricio/Desktop/MVP PUC/Checkin_eVTOL/checkin/lib/python3.12/site-packages/sqlalchemy/orm/session.py", line 4449, in _flush
    flush_context.execute()
  File "/Users/josepatricio/Desktop/MVP PUC/Checkin_eVTOL/checkin/lib/python3.12/site-packages/sqlalchemy/orm/unitofwork.py", line 466, in execute
    rec.execute(self)
  File "/Users/josepatricio/Desktop/MVP PUC/Checkin_eVTOL/checkin/lib/python3.12/site-packages/sqlalchemy/orm/unitofwork.py", line 642, in execute
    util.preloaded.orm_persistence.save_obj(
  File "/Users/josepatricio/Desktop/MVP PUC/Checkin_eVTOL/checkin/lib/python3.12/site-packages/sqlalchemy/orm/persistence.py", line 93, in save_obj
    _emit_insert_statements(
  File "/Users/josepatricio/Desktop/MVP PUC/Checkin_eVTOL/checkin/lib/python3.12/site-packages/sqlalchemy/orm/persistence.py", line 1233, in _emit_insert_statements
    result = connection.execute(
             ^^^^^^^^^^^^^^^^^^^
  File "/Users/josepatricio/Desktop/MVP PUC/Checkin_eVTOL/checkin/lib/python3.12/site-packages/sqlalchemy/engine/base.py", line 1416, in execute
    return meth(
           ^^^^^
  File "/Users/josepatricio/Desktop/MVP PUC/Checkin_eVTOL/checkin/lib/python3.12/site-packages/sqlalchemy/sql/elements.py", line 523, in _execute_on_connection
    return connection._execute_clauseelement(
           ^^^^^^^^^^^^^^^^^^^^^^^^^^^^^^^^^^
  File "/Users/josepatricio/Desktop/MVP PUC/Checkin_eVTOL/checkin/lib/python3.12/site-packages/sqlalchemy/engine/base.py", line 1638, in _execute_clauseelement
    ret = self._execute_context(
          ^^^^^^^^^^^^^^^^^^^^^^
  File "/Users/josepatricio/Desktop/MVP PUC/Checkin_eVTOL/checkin/lib/python3.12/site-packages/sqlalchemy/engine/base.py", line 1843, in _execute_context
    return self._exec_single_context(
           ^^^^^^^^^^^^^^^^^^^^^^^^^^
  File "/Users/josepatricio/Desktop/MVP PUC/Checkin_eVTOL/checkin/lib/python3.12/site-packages/sqlalchemy/engine/base.py", line 1983, in _exec_single_context
    self._handle_dbapi_exception(
  File "/Users/josepatricio/Desktop/MVP PUC/Checkin_eVTOL/checkin/lib/python3.12/site-packages/sqlalchemy/engine/base.py", line 2352, in _handle_dbapi_exception
    raise sqlalchemy_exception.with_traceback(exc_info[2]) from e
  File "/Users/josepatricio/Desktop/MVP PUC/Checkin_eVTOL/checkin/lib/python3.12/site-packages/sqlalchemy/engine/base.py", line 1964, in _exec_single_context
    self.dialect.do_execute(
  File "/Users/josepatricio/Desktop/MVP PUC/Checkin_eVTOL/checkin/lib/python3.12/site-packages/sqlalchemy/engine/default.py", line 945, in do_execute
    cursor.execute(statement, parameters)
sqlalchemy.exc.OperationalError: (sqlite3.OperationalError) database is locked
[SQL: INSERT INTO contato (telefone, tipo, data_insercao, passageiro) VALUES (?, ?, ?, ?)]
[parameters: ('21-9467-3456', 'Celular', '2025-04-11 23:29:23.728590', 3)]
(Background on this error at: https://sqlalche.me/e/20/e3q8)
[2025-04-11 23:45:01,367] INFO _log() L97   127.0.0.1 - - [11/Apr/2025 23:45:01] "[35m[1mPOST /contato HTTP/1.1[0m" 500 - - call_trace=/Users/josepatricio/Desktop/MVP PUC/Checkin_eVTOL/checkin/lib/python3.12/site-packages/werkzeug/_internal.py L97  
[2025-04-11 23:48:04,908] INFO _log() L97   [31m[1mWARNING: This is a development server. Do not use it in a production deployment. Use a production WSGI server instead.[0m
 * Running on all addresses (0.0.0.0)
 * Running on http://127.0.0.1:5001
 * Running on http://192.168.15.8:5001 - call_trace=/Users/josepatricio/Desktop/MVP PUC/Checkin_eVTOL/checkin/lib/python3.12/site-packages/werkzeug/_internal.py L97  
[2025-04-11 23:48:04,909] INFO _log() L97   [33mPress CTRL+C to quit[0m - call_trace=/Users/josepatricio/Desktop/MVP PUC/Checkin_eVTOL/checkin/lib/python3.12/site-packages/werkzeug/_internal.py L97  
[2025-04-11 23:48:21,592] INFO _log() L97   127.0.0.1 - - [11/Apr/2025 23:48:21] "GET /openapi/swagger HTTP/1.1" 200 - - call_trace=/Users/josepatricio/Desktop/MVP PUC/Checkin_eVTOL/checkin/lib/python3.12/site-packages/werkzeug/_internal.py L97  
[2025-04-11 23:48:21,627] INFO _log() L97   127.0.0.1 - - [11/Apr/2025 23:48:21] "[36mGET /openapi/swagger/js/swagger-ui-bundle.js HTTP/1.1[0m" 304 - - call_trace=/Users/josepatricio/Desktop/MVP PUC/Checkin_eVTOL/checkin/lib/python3.12/site-packages/werkzeug/_internal.py L97  
[2025-04-11 23:48:21,628] INFO _log() L97   127.0.0.1 - - [11/Apr/2025 23:48:21] "[36mGET /openapi/swagger/css/swagger-ui.css HTTP/1.1[0m" 304 - - call_trace=/Users/josepatricio/Desktop/MVP PUC/Checkin_eVTOL/checkin/lib/python3.12/site-packages/werkzeug/_internal.py L97  
[2025-04-11 23:48:21,637] INFO _log() L97   127.0.0.1 - - [11/Apr/2025 23:48:21] "[36mGET /openapi/swagger/js/swagger-ui-standalone-preset.js HTTP/1.1[0m" 304 - - call_trace=/Users/josepatricio/Desktop/MVP PUC/Checkin_eVTOL/checkin/lib/python3.12/site-packages/werkzeug/_internal.py L97  
[2025-04-11 23:48:21,765] INFO _log() L97   127.0.0.1 - - [11/Apr/2025 23:48:21] "GET /openapi/openapi.json HTTP/1.1" 200 - - call_trace=/Users/josepatricio/Desktop/MVP PUC/Checkin_eVTOL/checkin/lib/python3.12/site-packages/werkzeug/_internal.py L97  
[2025-04-11 23:49:03,805] INFO _log() L97   127.0.0.1 - - [11/Apr/2025 23:49:03] "OPTIONS /passageiro?cpf=433.345.437-26 HTTP/1.1" 200 - - call_trace=/Users/josepatricio/Desktop/MVP PUC/Checkin_eVTOL/checkin/lib/python3.12/site-packages/werkzeug/_internal.py L97  
[2025-04-11 23:49:03,822] WARNING del_passageiro() L171  Erro ao deletar passageiro #'433.345.437-26', Passageiro n√£o encontrado na base :/ - call_trace=/Users/josepatricio/Desktop/MVP PUC/Checkin_eVTOL/Checkin_back/app.py L171 
[2025-04-11 23:49:03,823] INFO _log() L97   127.0.0.1 - - [11/Apr/2025 23:49:03] "[33mDELETE /passageiro?cpf=433.345.437-26 HTTP/1.1[0m" 404 - - call_trace=/Users/josepatricio/Desktop/MVP PUC/Checkin_eVTOL/checkin/lib/python3.12/site-packages/werkzeug/_internal.py L97  
