[2025-04-09 20:41:52,318] ERROR log_exception() L875  Exception on /passageiro [POST] - call_trace=/Users/josepatricio/Desktop/MVP PUC/Checkin_eVTOL/checkin/lib/python3.12/site-packages/flask/app.py L875 
Traceback (most recent call last):
  File "/Users/josepatricio/Desktop/MVP PUC/Checkin_eVTOL/checkin/lib/python3.12/site-packages/flask/app.py", line 1511, in wsgi_app
    response = self.full_dispatch_request()
               ^^^^^^^^^^^^^^^^^^^^^^^^^^^^
  File "/Users/josepatricio/Desktop/MVP PUC/Checkin_eVTOL/checkin/lib/python3.12/site-packages/flask/app.py", line 919, in full_dispatch_request
    rv = self.handle_user_exception(e)
         ^^^^^^^^^^^^^^^^^^^^^^^^^^^^^
  File "/Users/josepatricio/Desktop/MVP PUC/Checkin_eVTOL/checkin/lib/python3.12/site-packages/flask_cors/extension.py", line 176, in wrapped_function
    return cors_after_request(app.make_response(f(*args, **kwargs)))
                                                ^^^^^^^^^^^^^^^^^^
  File "/Users/josepatricio/Desktop/MVP PUC/Checkin_eVTOL/checkin/lib/python3.12/site-packages/flask/app.py", line 917, in full_dispatch_request
    rv = self.dispatch_request()
         ^^^^^^^^^^^^^^^^^^^^^^^
  File "/Users/josepatricio/Desktop/MVP PUC/Checkin_eVTOL/checkin/lib/python3.12/site-packages/flask/app.py", line 902, in dispatch_request
    return self.ensure_sync(self.view_functions[rule.endpoint])(**view_args)  # type: ignore[no-any-return]
           ^^^^^^^^^^^^^^^^^^^^^^^^^^^^^^^^^^^^^^^^^^^^^^^^^^^^^^^^^^^^^^^^^
  File "/Users/josepatricio/Desktop/MVP PUC/Checkin_eVTOL/checkin/lib/python3.12/site-packages/flask_openapi3/scaffold.py", line 117, in view_func
    response = func(**func_kwargs)
               ^^^^^^^^^^^^^^^^^^^
  File "/Users/josepatricio/Desktop/MVP PUC/Checkin_eVTOL/Checkin_back/app.py", line 36, in add_passageiro
    passageiro = Passageiro(
                 ^^^^^^^^^^^
TypeError: __init__() got an unexpected keyword argument 'flight'
[2025-04-09 20:41:52,325] INFO _log() L97   127.0.0.1 - - [09/Apr/2025 20:41:52] "[35m[1mPOST /passageiro HTTP/1.1[0m" 500 - - call_trace=/Users/josepatricio/Desktop/MVP PUC/Checkin_eVTOL/checkin/lib/python3.12/site-packages/werkzeug/_internal.py L97  
[2025-04-09 20:42:21,680] INFO _log() L97   [31m[1mWARNING: This is a development server. Do not use it in a production deployment. Use a production WSGI server instead.[0m
 * Running on all addresses (0.0.0.0)
 * Running on http://127.0.0.1:5001
 * Running on http://192.168.15.8:5001 - call_trace=/Users/josepatricio/Desktop/MVP PUC/Checkin_eVTOL/checkin/lib/python3.12/site-packages/werkzeug/_internal.py L97  
[2025-04-09 20:42:21,680] INFO _log() L97   [33mPress CTRL+C to quit[0m - call_trace=/Users/josepatricio/Desktop/MVP PUC/Checkin_eVTOL/checkin/lib/python3.12/site-packages/werkzeug/_internal.py L97  
[2025-04-09 20:42:27,715] ERROR log_exception() L875  Exception on /passageiros [GET] - call_trace=/Users/josepatricio/Desktop/MVP PUC/Checkin_eVTOL/checkin/lib/python3.12/site-packages/flask/app.py L875 
Traceback (most recent call last):
  File "/Users/josepatricio/Desktop/MVP PUC/Checkin_eVTOL/checkin/lib/python3.12/site-packages/sqlalchemy/engine/base.py", line 1964, in _exec_single_context
    self.dialect.do_execute(
  File "/Users/josepatricio/Desktop/MVP PUC/Checkin_eVTOL/checkin/lib/python3.12/site-packages/sqlalchemy/engine/default.py", line 945, in do_execute
    cursor.execute(statement, parameters)
sqlite3.OperationalError: no such column: passageiro.flight

The above exception was the direct cause of the following exception:

Traceback (most recent call last):
  File "/Users/josepatricio/Desktop/MVP PUC/Checkin_eVTOL/checkin/lib/python3.12/site-packages/flask/app.py", line 1511, in wsgi_app
    response = self.full_dispatch_request()
               ^^^^^^^^^^^^^^^^^^^^^^^^^^^^
  File "/Users/josepatricio/Desktop/MVP PUC/Checkin_eVTOL/checkin/lib/python3.12/site-packages/flask/app.py", line 919, in full_dispatch_request
    rv = self.handle_user_exception(e)
         ^^^^^^^^^^^^^^^^^^^^^^^^^^^^^
  File "/Users/josepatricio/Desktop/MVP PUC/Checkin_eVTOL/checkin/lib/python3.12/site-packages/flask_cors/extension.py", line 176, in wrapped_function
    return cors_after_request(app.make_response(f(*args, **kwargs)))
                                                ^^^^^^^^^^^^^^^^^^
  File "/Users/josepatricio/Desktop/MVP PUC/Checkin_eVTOL/checkin/lib/python3.12/site-packages/flask/app.py", line 917, in full_dispatch_request
    rv = self.dispatch_request()
         ^^^^^^^^^^^^^^^^^^^^^^^
  File "/Users/josepatricio/Desktop/MVP PUC/Checkin_eVTOL/checkin/lib/python3.12/site-packages/flask/app.py", line 902, in dispatch_request
    return self.ensure_sync(self.view_functions[rule.endpoint])(**view_args)  # type: ignore[no-any-return]
           ^^^^^^^^^^^^^^^^^^^^^^^^^^^^^^^^^^^^^^^^^^^^^^^^^^^^^^^^^^^^^^^^^
  File "/Users/josepatricio/Desktop/MVP PUC/Checkin_eVTOL/checkin/lib/python3.12/site-packages/flask_openapi3/scaffold.py", line 117, in view_func
    response = func(**func_kwargs)
               ^^^^^^^^^^^^^^^^^^^
  File "/Users/josepatricio/Desktop/MVP PUC/Checkin_eVTOL/Checkin_back/app.py", line 75, in get_passageiros
    passageiros = session.query(Passageiro).all()
                  ^^^^^^^^^^^^^^^^^^^^^^^^^^^^^^^
  File "/Users/josepatricio/Desktop/MVP PUC/Checkin_eVTOL/checkin/lib/python3.12/site-packages/sqlalchemy/orm/query.py", line 2704, in all
    return self._iter().all()  # type: ignore
           ^^^^^^^^^^^^
  File "/Users/josepatricio/Desktop/MVP PUC/Checkin_eVTOL/checkin/lib/python3.12/site-packages/sqlalchemy/orm/query.py", line 2858, in _iter
    result: Union[ScalarResult[_T], Result[_T]] = self.session.execute(
                                                  ^^^^^^^^^^^^^^^^^^^^^
  File "/Users/josepatricio/Desktop/MVP PUC/Checkin_eVTOL/checkin/lib/python3.12/site-packages/sqlalchemy/orm/session.py", line 2365, in execute
    return self._execute_internal(
           ^^^^^^^^^^^^^^^^^^^^^^^
  File "/Users/josepatricio/Desktop/MVP PUC/Checkin_eVTOL/checkin/lib/python3.12/site-packages/sqlalchemy/orm/session.py", line 2251, in _execute_internal
    result: Result[Any] = compile_state_cls.orm_execute_statement(
                          ^^^^^^^^^^^^^^^^^^^^^^^^^^^^^^^^^^^^^^^^
  File "/Users/josepatricio/Desktop/MVP PUC/Checkin_eVTOL/checkin/lib/python3.12/site-packages/sqlalchemy/orm/context.py", line 306, in orm_execute_statement
    result = conn.execute(
             ^^^^^^^^^^^^^
  File "/Users/josepatricio/Desktop/MVP PUC/Checkin_eVTOL/checkin/lib/python3.12/site-packages/sqlalchemy/engine/base.py", line 1416, in execute
    return meth(
           ^^^^^
  File "/Users/josepatricio/Desktop/MVP PUC/Checkin_eVTOL/checkin/lib/python3.12/site-packages/sqlalchemy/sql/elements.py", line 523, in _execute_on_connection
    return connection._execute_clauseelement(
           ^^^^^^^^^^^^^^^^^^^^^^^^^^^^^^^^^^
  File "/Users/josepatricio/Desktop/MVP PUC/Checkin_eVTOL/checkin/lib/python3.12/site-packages/sqlalchemy/engine/base.py", line 1638, in _execute_clauseelement
    ret = self._execute_context(
          ^^^^^^^^^^^^^^^^^^^^^^
  File "/Users/josepatricio/Desktop/MVP PUC/Checkin_eVTOL/checkin/lib/python3.12/site-packages/sqlalchemy/engine/base.py", line 1843, in _execute_context
    return self._exec_single_context(
           ^^^^^^^^^^^^^^^^^^^^^^^^^^
  File "/Users/josepatricio/Desktop/MVP PUC/Checkin_eVTOL/checkin/lib/python3.12/site-packages/sqlalchemy/engine/base.py", line 1983, in _exec_single_context
    self._handle_dbapi_exception(
  File "/Users/josepatricio/Desktop/MVP PUC/Checkin_eVTOL/checkin/lib/python3.12/site-packages/sqlalchemy/engine/base.py", line 2352, in _handle_dbapi_exception
    raise sqlalchemy_exception.with_traceback(exc_info[2]) from e
  File "/Users/josepatricio/Desktop/MVP PUC/Checkin_eVTOL/checkin/lib/python3.12/site-packages/sqlalchemy/engine/base.py", line 1964, in _exec_single_context
    self.dialect.do_execute(
  File "/Users/josepatricio/Desktop/MVP PUC/Checkin_eVTOL/checkin/lib/python3.12/site-packages/sqlalchemy/engine/default.py", line 945, in do_execute
    cursor.execute(statement, parameters)
sqlalchemy.exc.OperationalError: (sqlite3.OperationalError) no such column: passageiro.flight
[SQL: SELECT passageiro.pk_passageiro AS passageiro_pk_passageiro, passageiro.nome AS passageiro_nome, passageiro.cpf AS passageiro_cpf, passageiro.flight AS passageiro_flight, passageiro.data_insercao AS passageiro_data_insercao 
FROM passageiro]
(Background on this error at: https://sqlalche.me/e/20/e3q8)
[2025-04-09 20:42:27,734] INFO _log() L97   127.0.0.1 - - [09/Apr/2025 20:42:27] "[35m[1mGET /passageiros HTTP/1.1[0m" 500 - - call_trace=/Users/josepatricio/Desktop/MVP PUC/Checkin_eVTOL/checkin/lib/python3.12/site-packages/werkzeug/_internal.py L97  
[2025-04-09 20:42:44,399] WARNING add_passageiro() L60   Erro ao adicionar passageiro 'JOAO', '001123456-87', N√£o foi poss√≠vel salvar novo item :/ - call_trace=/Users/josepatricio/Desktop/MVP PUC/Checkin_eVTOL/Checkin_back/app.py L60  
[2025-04-09 20:42:44,400] INFO _log() L97   127.0.0.1 - - [09/Apr/2025 20:42:44] "[31m[1mPOST /passageiro HTTP/1.1[0m" 400 - - call_trace=/Users/josepatricio/Desktop/MVP PUC/Checkin_eVTOL/checkin/lib/python3.12/site-packages/werkzeug/_internal.py L97  
[2025-04-09 20:43:31,767] INFO _log() L97   127.0.0.1 - - [09/Apr/2025 20:43:31] "OPTIONS /passageiro HTTP/1.1" 200 - - call_trace=/Users/josepatricio/Desktop/MVP PUC/Checkin_eVTOL/checkin/lib/python3.12/site-packages/werkzeug/_internal.py L97  
[2025-04-09 20:43:31,786] INFO _log() L97   127.0.0.1 - - [09/Apr/2025 20:43:31] "[31m[1mPUT /passageiro HTTP/1.1[0m" 422 - - call_trace=/Users/josepatricio/Desktop/MVP PUC/Checkin_eVTOL/checkin/lib/python3.12/site-packages/werkzeug/_internal.py L97  
